[2024-09-17T11:57:58.709+0100] {processor.py:186} INFO - Started process (PID=89824) to work on /Users/ds2718/Documents/test_python_airflow/airflow/dags/examp_dag_sec.py
[2024-09-17T11:57:58.709+0100] {processor.py:914} INFO - Processing file /Users/ds2718/Documents/test_python_airflow/airflow/dags/examp_dag_sec.py for tasks to queue
[2024-09-17T11:57:58.710+0100] {logging_mixin.py:190} INFO - [2024-09-17T11:57:58.710+0100] {dagbag.py:587} INFO - Filling up the DagBag from /Users/ds2718/Documents/test_python_airflow/airflow/dags/examp_dag_sec.py
[2024-09-17T11:57:58.774+0100] {logging_mixin.py:190} INFO - [2024-09-17T11:57:58.754+0100] {dagbag.py:386} ERROR - Failed to import: /Users/ds2718/Documents/test_python_airflow/airflow/dags/examp_dag_sec.py
Traceback (most recent call last):
  File "/Users/ds2718/Documents/test_python_airflow/airflow/py_venv/lib/python3.12/site-packages/airflow/models/dagbag.py", line 382, in parse
    loader.exec_module(new_module)
  File "<frozen importlib._bootstrap_external>", line 995, in exec_module
  File "<frozen importlib._bootstrap>", line 488, in _call_with_frames_removed
  File "/Users/ds2718/Documents/test_python_airflow/airflow/dags/examp_dag_sec.py", line 5, in <module>
    import ssh_connection
ModuleNotFoundError: No module named 'ssh_connection'
[2024-09-17T11:57:58.774+0100] {processor.py:927} WARNING - No viable dags retrieved from /Users/ds2718/Documents/test_python_airflow/airflow/dags/examp_dag_sec.py
[2024-09-17T11:57:58.833+0100] {processor.py:208} INFO - Processing /Users/ds2718/Documents/test_python_airflow/airflow/dags/examp_dag_sec.py took 0.132 seconds
[2024-09-17T12:00:47.795+0100] {processor.py:186} INFO - Started process (PID=90118) to work on /Users/ds2718/Documents/test_python_airflow/airflow/dags/examp_dag_sec.py
[2024-09-17T12:00:47.796+0100] {processor.py:914} INFO - Processing file /Users/ds2718/Documents/test_python_airflow/airflow/dags/examp_dag_sec.py for tasks to queue
[2024-09-17T12:00:47.796+0100] {logging_mixin.py:190} INFO - [2024-09-17T12:00:47.796+0100] {dagbag.py:587} INFO - Filling up the DagBag from /Users/ds2718/Documents/test_python_airflow/airflow/dags/examp_dag_sec.py
[2024-09-17T12:00:48.510+0100] {logging_mixin.py:190} INFO - [2024-09-17T12:00:48.509+0100] {transport.py:1923} INFO - Connected (version 2.0, client OpenSSH_8.0)
[2024-09-17T12:00:49.635+0100] {logging_mixin.py:190} INFO - [2024-09-17T12:00:49.634+0100] {transport.py:1923} INFO - Auth banner: b'\n        <><><><><><><><><><><><><><><><><><><><><><><><><><><><><><>\n        <>                                                        <>\n        <>                        !WARNING!                       <>\n        <>                                                        <>\n        <>                    RCS CSD3 Facility                   <>\n        <>             Unauthorised Access Prohibited             <>\n        <>    Use of this system constitutes acceptance of our    <>\n        <>                     policies - see                     <>\n        <> http://docs.hpc.cam.ac.uk/hpc/user-guide/policies.html <>\n        <>                                                        <>\n        <><><><><><><><><><><><><><><><><><><><><><><><><><><><><><>\n\n\n'
[2024-09-17T12:00:49.636+0100] {logging_mixin.py:190} INFO - [2024-09-17T12:00:49.635+0100] {transport.py:1923} INFO - Authentication continues...
[2024-09-17T12:00:49.789+0100] {logging_mixin.py:190} INFO - TOTP Verification Code: 
[2024-09-17T12:00:49.801+0100] {logging_mixin.py:190} INFO - [2024-09-17T12:00:49.789+0100] {dagbag.py:386} ERROR - Failed to import: /Users/ds2718/Documents/test_python_airflow/airflow/dags/examp_dag_sec.py
Traceback (most recent call last):
  File "/Users/ds2718/Documents/test_python_airflow/airflow/ssh_connection/custom_client.py", line 24, in client_conn
    transport.auth_interactive_dumb(self.username)
  File "/Users/ds2718/Documents/test_python_airflow/airflow/py_venv/lib/python3.12/site-packages/paramiko/transport.py", line 1764, in auth_interactive_dumb
    return self.auth_interactive(username, handler, submethods)
           ^^^^^^^^^^^^^^^^^^^^^^^^^^^^^^^^^^^^^^^^^^^^^^^^^^^^
  File "/Users/ds2718/Documents/test_python_airflow/airflow/py_venv/lib/python3.12/site-packages/paramiko/transport.py", line 1741, in auth_interactive
    return self.auth_handler.wait_for_response(my_event)
           ^^^^^^^^^^^^^^^^^^^^^^^^^^^^^^^^^^^^^^^^^^^^^
  File "/Users/ds2718/Documents/test_python_airflow/airflow/py_venv/lib/python3.12/site-packages/paramiko/auth_handler.py", line 248, in wait_for_response
    raise e
paramiko.ssh_exception.AuthenticationException: Authentication failed: transport shut down or saw EOF

During handling of the above exception, another exception occurred:

Traceback (most recent call last):
  File "/Users/ds2718/Documents/test_python_airflow/airflow/py_venv/lib/python3.12/site-packages/airflow/models/dagbag.py", line 382, in parse
    loader.exec_module(new_module)
  File "<frozen importlib._bootstrap_external>", line 995, in exec_module
  File "<frozen importlib._bootstrap>", line 488, in _call_with_frames_removed
  File "/Users/ds2718/Documents/test_python_airflow/airflow/dags/examp_dag_sec.py", line 8, in <module>
    from ssh_connection.custom_ssh_hook import custom_ssh_hook
  File "/Users/ds2718/Documents/test_python_airflow/airflow/ssh_connection/custom_ssh_hook.py", line 14, in <module>
    ssh_conn = customSSHConnect().client_conn()
               ^^^^^^^^^^^^^^^^^^^^^^^^^^^^^^^^
  File "/Users/ds2718/Documents/test_python_airflow/airflow/ssh_connection/custom_client.py", line 30, in client_conn
    raise(f"Error initiation ssh connection {e}")
TypeError: exceptions must derive from BaseException
[2024-09-17T12:00:49.801+0100] {processor.py:927} WARNING - No viable dags retrieved from /Users/ds2718/Documents/test_python_airflow/airflow/dags/examp_dag_sec.py
[2024-09-17T12:00:49.885+0100] {processor.py:208} INFO - Processing /Users/ds2718/Documents/test_python_airflow/airflow/dags/examp_dag_sec.py took 2.095 seconds
[2024-09-17T12:01:21.424+0100] {processor.py:186} INFO - Started process (PID=90175) to work on /Users/ds2718/Documents/test_python_airflow/airflow/dags/examp_dag_sec.py
[2024-09-17T12:01:21.426+0100] {processor.py:914} INFO - Processing file /Users/ds2718/Documents/test_python_airflow/airflow/dags/examp_dag_sec.py for tasks to queue
[2024-09-17T12:01:21.426+0100] {logging_mixin.py:190} INFO - [2024-09-17T12:01:21.426+0100] {dagbag.py:587} INFO - Filling up the DagBag from /Users/ds2718/Documents/test_python_airflow/airflow/dags/examp_dag_sec.py
[2024-09-17T12:01:21.778+0100] {logging_mixin.py:190} INFO - [2024-09-17T12:01:21.778+0100] {transport.py:1923} INFO - Connected (version 2.0, client OpenSSH_8.0)
[2024-09-17T12:01:23.646+0100] {logging_mixin.py:190} INFO - [2024-09-17T12:01:23.645+0100] {transport.py:1923} INFO - Auth banner: b'\n        <><><><><><><><><><><><><><><><><><><><><><><><><><><><><><>\n        <>                                                        <>\n        <>                        !WARNING!                       <>\n        <>                                                        <>\n        <>                    RCS CSD3 Facility                   <>\n        <>             Unauthorised Access Prohibited             <>\n        <>    Use of this system constitutes acceptance of our    <>\n        <>                     policies - see                     <>\n        <> http://docs.hpc.cam.ac.uk/hpc/user-guide/policies.html <>\n        <>                                                        <>\n        <><><><><><><><><><><><><><><><><><><><><><><><><><><><><><>\n\n\n'
[2024-09-17T12:01:23.646+0100] {logging_mixin.py:190} INFO - [2024-09-17T12:01:23.646+0100] {transport.py:1923} INFO - Authentication continues...
[2024-09-17T12:01:23.803+0100] {logging_mixin.py:190} INFO - TOTP Verification Code: 
[2024-09-17T12:01:23.808+0100] {logging_mixin.py:190} INFO - [2024-09-17T12:01:23.804+0100] {dagbag.py:386} ERROR - Failed to import: /Users/ds2718/Documents/test_python_airflow/airflow/dags/examp_dag_sec.py
Traceback (most recent call last):
  File "/Users/ds2718/Documents/test_python_airflow/airflow/ssh_connection/custom_client.py", line 24, in client_conn
    transport.auth_interactive_dumb(self.username)
  File "/Users/ds2718/Documents/test_python_airflow/airflow/py_venv/lib/python3.12/site-packages/paramiko/transport.py", line 1764, in auth_interactive_dumb
    return self.auth_interactive(username, handler, submethods)
           ^^^^^^^^^^^^^^^^^^^^^^^^^^^^^^^^^^^^^^^^^^^^^^^^^^^^
  File "/Users/ds2718/Documents/test_python_airflow/airflow/py_venv/lib/python3.12/site-packages/paramiko/transport.py", line 1741, in auth_interactive
    return self.auth_handler.wait_for_response(my_event)
           ^^^^^^^^^^^^^^^^^^^^^^^^^^^^^^^^^^^^^^^^^^^^^
  File "/Users/ds2718/Documents/test_python_airflow/airflow/py_venv/lib/python3.12/site-packages/paramiko/auth_handler.py", line 248, in wait_for_response
    raise e
paramiko.ssh_exception.AuthenticationException: Authentication failed: transport shut down or saw EOF

During handling of the above exception, another exception occurred:

Traceback (most recent call last):
  File "/Users/ds2718/Documents/test_python_airflow/airflow/py_venv/lib/python3.12/site-packages/airflow/models/dagbag.py", line 382, in parse
    loader.exec_module(new_module)
  File "<frozen importlib._bootstrap_external>", line 995, in exec_module
  File "<frozen importlib._bootstrap>", line 488, in _call_with_frames_removed
  File "/Users/ds2718/Documents/test_python_airflow/airflow/dags/examp_dag_sec.py", line 8, in <module>
    from ssh_connection.custom_ssh_hook import custom_ssh_hook
  File "/Users/ds2718/Documents/test_python_airflow/airflow/ssh_connection/custom_ssh_hook.py", line 14, in <module>
    ssh_conn = customSSHConnect().client_conn()
               ^^^^^^^^^^^^^^^^^^^^^^^^^^^^^^^^
  File "/Users/ds2718/Documents/test_python_airflow/airflow/ssh_connection/custom_client.py", line 30, in client_conn
    raise(f"Error initiation ssh connection {e}")
TypeError: exceptions must derive from BaseException
[2024-09-17T12:01:23.809+0100] {processor.py:927} WARNING - No viable dags retrieved from /Users/ds2718/Documents/test_python_airflow/airflow/dags/examp_dag_sec.py
[2024-09-17T12:01:23.913+0100] {processor.py:208} INFO - Processing /Users/ds2718/Documents/test_python_airflow/airflow/dags/examp_dag_sec.py took 2.493 seconds
[2024-09-17T12:01:55.639+0100] {processor.py:186} INFO - Started process (PID=90298) to work on /Users/ds2718/Documents/test_python_airflow/airflow/dags/examp_dag_sec.py
[2024-09-17T12:01:55.640+0100] {processor.py:914} INFO - Processing file /Users/ds2718/Documents/test_python_airflow/airflow/dags/examp_dag_sec.py for tasks to queue
[2024-09-17T12:01:55.640+0100] {logging_mixin.py:190} INFO - [2024-09-17T12:01:55.640+0100] {dagbag.py:587} INFO - Filling up the DagBag from /Users/ds2718/Documents/test_python_airflow/airflow/dags/examp_dag_sec.py
[2024-09-17T12:01:58.193+0100] {logging_mixin.py:190} INFO - [2024-09-17T12:01:58.192+0100] {transport.py:1923} INFO - Connected (version 2.0, client OpenSSH_8.0)
[2024-09-17T12:01:59.695+0100] {logging_mixin.py:190} INFO - [2024-09-17T12:01:59.692+0100] {transport.py:1923} INFO - Auth banner: b'\n        <><><><><><><><><><><><><><><><><><><><><><><><><><><><><><>\n        <>                                                        <>\n        <>                        !WARNING!                       <>\n        <>                                                        <>\n        <>                    RCS CSD3 Facility                   <>\n        <>             Unauthorised Access Prohibited             <>\n        <>    Use of this system constitutes acceptance of our    <>\n        <>                     policies - see                     <>\n        <> http://docs.hpc.cam.ac.uk/hpc/user-guide/policies.html <>\n        <>                                                        <>\n        <><><><><><><><><><><><><><><><><><><><><><><><><><><><><><>\n\n\n'
[2024-09-17T12:01:59.696+0100] {logging_mixin.py:190} INFO - [2024-09-17T12:01:59.695+0100] {transport.py:1923} INFO - Authentication continues...
[2024-09-17T12:01:59.882+0100] {logging_mixin.py:190} INFO - TOTP Verification Code: 
[2024-09-17T12:01:59.906+0100] {logging_mixin.py:190} INFO - [2024-09-17T12:01:59.893+0100] {dagbag.py:386} ERROR - Failed to import: /Users/ds2718/Documents/test_python_airflow/airflow/dags/examp_dag_sec.py
Traceback (most recent call last):
  File "/Users/ds2718/Documents/test_python_airflow/airflow/ssh_connection/custom_client.py", line 24, in client_conn
    transport.auth_interactive_dumb(self.username)
  File "/Users/ds2718/Documents/test_python_airflow/airflow/py_venv/lib/python3.12/site-packages/paramiko/transport.py", line 1764, in auth_interactive_dumb
    return self.auth_interactive(username, handler, submethods)
           ^^^^^^^^^^^^^^^^^^^^^^^^^^^^^^^^^^^^^^^^^^^^^^^^^^^^
  File "/Users/ds2718/Documents/test_python_airflow/airflow/py_venv/lib/python3.12/site-packages/paramiko/transport.py", line 1741, in auth_interactive
    return self.auth_handler.wait_for_response(my_event)
           ^^^^^^^^^^^^^^^^^^^^^^^^^^^^^^^^^^^^^^^^^^^^^
  File "/Users/ds2718/Documents/test_python_airflow/airflow/py_venv/lib/python3.12/site-packages/paramiko/auth_handler.py", line 248, in wait_for_response
    raise e
paramiko.ssh_exception.AuthenticationException: Authentication failed: transport shut down or saw EOF

During handling of the above exception, another exception occurred:

Traceback (most recent call last):
  File "/Users/ds2718/Documents/test_python_airflow/airflow/py_venv/lib/python3.12/site-packages/airflow/models/dagbag.py", line 382, in parse
    loader.exec_module(new_module)
  File "<frozen importlib._bootstrap_external>", line 995, in exec_module
  File "<frozen importlib._bootstrap>", line 488, in _call_with_frames_removed
  File "/Users/ds2718/Documents/test_python_airflow/airflow/dags/examp_dag_sec.py", line 8, in <module>
    from ssh_connection.custom_ssh_hook import custom_ssh_hook
  File "/Users/ds2718/Documents/test_python_airflow/airflow/ssh_connection/custom_ssh_hook.py", line 14, in <module>
    ssh_conn = customSSHConnect().client_conn()
               ^^^^^^^^^^^^^^^^^^^^^^^^^^^^^^^^
  File "/Users/ds2718/Documents/test_python_airflow/airflow/ssh_connection/custom_client.py", line 30, in client_conn
    raise(f"Error initiation ssh connection {e}")
TypeError: exceptions must derive from BaseException
[2024-09-17T12:01:59.907+0100] {processor.py:927} WARNING - No viable dags retrieved from /Users/ds2718/Documents/test_python_airflow/airflow/dags/examp_dag_sec.py
[2024-09-17T12:02:00.061+0100] {processor.py:208} INFO - Processing /Users/ds2718/Documents/test_python_airflow/airflow/dags/examp_dag_sec.py took 4.428 seconds
[2024-09-17T12:02:31.833+0100] {processor.py:186} INFO - Started process (PID=90370) to work on /Users/ds2718/Documents/test_python_airflow/airflow/dags/examp_dag_sec.py
[2024-09-17T12:02:31.834+0100] {processor.py:914} INFO - Processing file /Users/ds2718/Documents/test_python_airflow/airflow/dags/examp_dag_sec.py for tasks to queue
[2024-09-17T12:02:31.835+0100] {logging_mixin.py:190} INFO - [2024-09-17T12:02:31.835+0100] {dagbag.py:587} INFO - Filling up the DagBag from /Users/ds2718/Documents/test_python_airflow/airflow/dags/examp_dag_sec.py
[2024-09-17T12:02:32.074+0100] {logging_mixin.py:190} INFO - [2024-09-17T12:02:32.074+0100] {transport.py:1923} INFO - Connected (version 2.0, client OpenSSH_8.0)
[2024-09-17T12:02:33.003+0100] {logging_mixin.py:190} INFO - [2024-09-17T12:02:33.002+0100] {transport.py:1923} INFO - Auth banner: b'\n        <><><><><><><><><><><><><><><><><><><><><><><><><><><><><><>\n        <>                                                        <>\n        <>                        !WARNING!                       <>\n        <>                                                        <>\n        <>                    RCS CSD3 Facility                   <>\n        <>             Unauthorised Access Prohibited             <>\n        <>    Use of this system constitutes acceptance of our    <>\n        <>                     policies - see                     <>\n        <> http://docs.hpc.cam.ac.uk/hpc/user-guide/policies.html <>\n        <>                                                        <>\n        <><><><><><><><><><><><><><><><><><><><><><><><><><><><><><>\n\n\n'
[2024-09-17T12:02:33.003+0100] {logging_mixin.py:190} INFO - [2024-09-17T12:02:33.003+0100] {transport.py:1923} INFO - Authentication continues...
[2024-09-17T12:02:33.222+0100] {logging_mixin.py:190} INFO - TOTP Verification Code: 
[2024-09-17T12:02:33.231+0100] {logging_mixin.py:190} INFO - [2024-09-17T12:02:33.223+0100] {dagbag.py:386} ERROR - Failed to import: /Users/ds2718/Documents/test_python_airflow/airflow/dags/examp_dag_sec.py
Traceback (most recent call last):
  File "/Users/ds2718/Documents/test_python_airflow/airflow/ssh_connection/custom_client.py", line 24, in client_conn
    transport.auth_interactive_dumb(self.username)
  File "/Users/ds2718/Documents/test_python_airflow/airflow/py_venv/lib/python3.12/site-packages/paramiko/transport.py", line 1764, in auth_interactive_dumb
    return self.auth_interactive(username, handler, submethods)
           ^^^^^^^^^^^^^^^^^^^^^^^^^^^^^^^^^^^^^^^^^^^^^^^^^^^^
  File "/Users/ds2718/Documents/test_python_airflow/airflow/py_venv/lib/python3.12/site-packages/paramiko/transport.py", line 1741, in auth_interactive
    return self.auth_handler.wait_for_response(my_event)
           ^^^^^^^^^^^^^^^^^^^^^^^^^^^^^^^^^^^^^^^^^^^^^
  File "/Users/ds2718/Documents/test_python_airflow/airflow/py_venv/lib/python3.12/site-packages/paramiko/auth_handler.py", line 248, in wait_for_response
    raise e
paramiko.ssh_exception.AuthenticationException: Authentication failed: transport shut down or saw EOF

During handling of the above exception, another exception occurred:

Traceback (most recent call last):
  File "/Users/ds2718/Documents/test_python_airflow/airflow/py_venv/lib/python3.12/site-packages/airflow/models/dagbag.py", line 382, in parse
    loader.exec_module(new_module)
  File "<frozen importlib._bootstrap_external>", line 995, in exec_module
  File "<frozen importlib._bootstrap>", line 488, in _call_with_frames_removed
  File "/Users/ds2718/Documents/test_python_airflow/airflow/dags/examp_dag_sec.py", line 8, in <module>
    from ssh_connection.custom_ssh_hook import custom_ssh_hook
  File "/Users/ds2718/Documents/test_python_airflow/airflow/ssh_connection/custom_ssh_hook.py", line 14, in <module>
    ssh_conn = customSSHConnect().client_conn()
               ^^^^^^^^^^^^^^^^^^^^^^^^^^^^^^^^
  File "/Users/ds2718/Documents/test_python_airflow/airflow/ssh_connection/custom_client.py", line 30, in client_conn
    raise(f"Error initiation ssh connection {e}")
TypeError: exceptions must derive from BaseException
[2024-09-17T12:02:33.232+0100] {processor.py:927} WARNING - No viable dags retrieved from /Users/ds2718/Documents/test_python_airflow/airflow/dags/examp_dag_sec.py
[2024-09-17T12:02:33.322+0100] {processor.py:208} INFO - Processing /Users/ds2718/Documents/test_python_airflow/airflow/dags/examp_dag_sec.py took 1.493 seconds
[2024-09-17T12:03:04.788+0100] {processor.py:186} INFO - Started process (PID=90513) to work on /Users/ds2718/Documents/test_python_airflow/airflow/dags/examp_dag_sec.py
[2024-09-17T12:03:04.789+0100] {processor.py:914} INFO - Processing file /Users/ds2718/Documents/test_python_airflow/airflow/dags/examp_dag_sec.py for tasks to queue
[2024-09-17T12:03:04.790+0100] {logging_mixin.py:190} INFO - [2024-09-17T12:03:04.790+0100] {dagbag.py:587} INFO - Filling up the DagBag from /Users/ds2718/Documents/test_python_airflow/airflow/dags/examp_dag_sec.py
[2024-09-17T12:03:05.047+0100] {logging_mixin.py:190} INFO - [2024-09-17T12:03:05.045+0100] {transport.py:1923} INFO - Connected (version 2.0, client OpenSSH_8.0)
[2024-09-17T12:03:06.461+0100] {logging_mixin.py:190} INFO - [2024-09-17T12:03:06.461+0100] {transport.py:1923} INFO - Auth banner: b'\n        <><><><><><><><><><><><><><><><><><><><><><><><><><><><><><>\n        <>                                                        <>\n        <>                        !WARNING!                       <>\n        <>                                                        <>\n        <>                    RCS CSD3 Facility                   <>\n        <>             Unauthorised Access Prohibited             <>\n        <>    Use of this system constitutes acceptance of our    <>\n        <>                     policies - see                     <>\n        <> http://docs.hpc.cam.ac.uk/hpc/user-guide/policies.html <>\n        <>                                                        <>\n        <><><><><><><><><><><><><><><><><><><><><><><><><><><><><><>\n\n\n'
[2024-09-17T12:03:06.462+0100] {logging_mixin.py:190} INFO - [2024-09-17T12:03:06.462+0100] {transport.py:1923} INFO - Authentication continues...
[2024-09-17T12:03:06.713+0100] {logging_mixin.py:190} INFO - TOTP Verification Code: 
[2024-09-17T12:03:06.721+0100] {logging_mixin.py:190} INFO - [2024-09-17T12:03:06.714+0100] {dagbag.py:386} ERROR - Failed to import: /Users/ds2718/Documents/test_python_airflow/airflow/dags/examp_dag_sec.py
Traceback (most recent call last):
  File "/Users/ds2718/Documents/test_python_airflow/airflow/ssh_connection/custom_client.py", line 24, in client_conn
    transport.auth_interactive_dumb(self.username)
  File "/Users/ds2718/Documents/test_python_airflow/airflow/py_venv/lib/python3.12/site-packages/paramiko/transport.py", line 1764, in auth_interactive_dumb
    return self.auth_interactive(username, handler, submethods)
           ^^^^^^^^^^^^^^^^^^^^^^^^^^^^^^^^^^^^^^^^^^^^^^^^^^^^
  File "/Users/ds2718/Documents/test_python_airflow/airflow/py_venv/lib/python3.12/site-packages/paramiko/transport.py", line 1741, in auth_interactive
    return self.auth_handler.wait_for_response(my_event)
           ^^^^^^^^^^^^^^^^^^^^^^^^^^^^^^^^^^^^^^^^^^^^^
  File "/Users/ds2718/Documents/test_python_airflow/airflow/py_venv/lib/python3.12/site-packages/paramiko/auth_handler.py", line 248, in wait_for_response
    raise e
paramiko.ssh_exception.AuthenticationException: Authentication failed: transport shut down or saw EOF

During handling of the above exception, another exception occurred:

Traceback (most recent call last):
  File "/Users/ds2718/Documents/test_python_airflow/airflow/py_venv/lib/python3.12/site-packages/airflow/models/dagbag.py", line 382, in parse
    loader.exec_module(new_module)
  File "<frozen importlib._bootstrap_external>", line 995, in exec_module
  File "<frozen importlib._bootstrap>", line 488, in _call_with_frames_removed
  File "/Users/ds2718/Documents/test_python_airflow/airflow/dags/examp_dag_sec.py", line 8, in <module>
    from ssh_connection.custom_ssh_hook import custom_ssh_hook
  File "/Users/ds2718/Documents/test_python_airflow/airflow/ssh_connection/custom_ssh_hook.py", line 14, in <module>
    ssh_conn = customSSHConnect().client_conn()
               ^^^^^^^^^^^^^^^^^^^^^^^^^^^^^^^^
  File "/Users/ds2718/Documents/test_python_airflow/airflow/ssh_connection/custom_client.py", line 30, in client_conn
    raise(f"Error initiation ssh connection {e}")
TypeError: exceptions must derive from BaseException
[2024-09-17T12:03:06.722+0100] {processor.py:927} WARNING - No viable dags retrieved from /Users/ds2718/Documents/test_python_airflow/airflow/dags/examp_dag_sec.py
[2024-09-17T12:03:06.810+0100] {processor.py:208} INFO - Processing /Users/ds2718/Documents/test_python_airflow/airflow/dags/examp_dag_sec.py took 2.026 seconds
[2024-09-17T12:03:38.175+0100] {processor.py:186} INFO - Started process (PID=90572) to work on /Users/ds2718/Documents/test_python_airflow/airflow/dags/examp_dag_sec.py
[2024-09-17T12:03:38.180+0100] {processor.py:914} INFO - Processing file /Users/ds2718/Documents/test_python_airflow/airflow/dags/examp_dag_sec.py for tasks to queue
[2024-09-17T12:03:38.181+0100] {logging_mixin.py:190} INFO - [2024-09-17T12:03:38.181+0100] {dagbag.py:587} INFO - Filling up the DagBag from /Users/ds2718/Documents/test_python_airflow/airflow/dags/examp_dag_sec.py
[2024-09-17T12:03:38.723+0100] {logging_mixin.py:190} INFO - [2024-09-17T12:03:38.722+0100] {transport.py:1923} INFO - Connected (version 2.0, client OpenSSH_8.0)
[2024-09-17T12:03:39.642+0100] {logging_mixin.py:190} INFO - [2024-09-17T12:03:39.642+0100] {transport.py:1923} INFO - Auth banner: b'\n        <><><><><><><><><><><><><><><><><><><><><><><><><><><><><><>\n        <>                                                        <>\n        <>                        !WARNING!                       <>\n        <>                                                        <>\n        <>                    RCS CSD3 Facility                   <>\n        <>             Unauthorised Access Prohibited             <>\n        <>    Use of this system constitutes acceptance of our    <>\n        <>                     policies - see                     <>\n        <> http://docs.hpc.cam.ac.uk/hpc/user-guide/policies.html <>\n        <>                                                        <>\n        <><><><><><><><><><><><><><><><><><><><><><><><><><><><><><>\n\n\n'
[2024-09-17T12:03:39.642+0100] {logging_mixin.py:190} INFO - [2024-09-17T12:03:39.642+0100] {transport.py:1923} INFO - Authentication continues...
[2024-09-17T12:03:39.958+0100] {logging_mixin.py:190} INFO - TOTP Verification Code: 
[2024-09-17T12:03:39.964+0100] {logging_mixin.py:190} INFO - [2024-09-17T12:03:39.958+0100] {dagbag.py:386} ERROR - Failed to import: /Users/ds2718/Documents/test_python_airflow/airflow/dags/examp_dag_sec.py
Traceback (most recent call last):
  File "/Users/ds2718/Documents/test_python_airflow/airflow/ssh_connection/custom_client.py", line 24, in client_conn
    transport.auth_interactive_dumb(self.username)
  File "/Users/ds2718/Documents/test_python_airflow/airflow/py_venv/lib/python3.12/site-packages/paramiko/transport.py", line 1764, in auth_interactive_dumb
    return self.auth_interactive(username, handler, submethods)
           ^^^^^^^^^^^^^^^^^^^^^^^^^^^^^^^^^^^^^^^^^^^^^^^^^^^^
  File "/Users/ds2718/Documents/test_python_airflow/airflow/py_venv/lib/python3.12/site-packages/paramiko/transport.py", line 1741, in auth_interactive
    return self.auth_handler.wait_for_response(my_event)
           ^^^^^^^^^^^^^^^^^^^^^^^^^^^^^^^^^^^^^^^^^^^^^
  File "/Users/ds2718/Documents/test_python_airflow/airflow/py_venv/lib/python3.12/site-packages/paramiko/auth_handler.py", line 248, in wait_for_response
    raise e
paramiko.ssh_exception.AuthenticationException: Authentication failed: transport shut down or saw EOF

During handling of the above exception, another exception occurred:

Traceback (most recent call last):
  File "/Users/ds2718/Documents/test_python_airflow/airflow/py_venv/lib/python3.12/site-packages/airflow/models/dagbag.py", line 382, in parse
    loader.exec_module(new_module)
  File "<frozen importlib._bootstrap_external>", line 995, in exec_module
  File "<frozen importlib._bootstrap>", line 488, in _call_with_frames_removed
  File "/Users/ds2718/Documents/test_python_airflow/airflow/dags/examp_dag_sec.py", line 8, in <module>
    from ssh_connection.custom_ssh_hook import custom_ssh_hook
  File "/Users/ds2718/Documents/test_python_airflow/airflow/ssh_connection/custom_ssh_hook.py", line 14, in <module>
    ssh_conn = customSSHConnect().client_conn()
               ^^^^^^^^^^^^^^^^^^^^^^^^^^^^^^^^
  File "/Users/ds2718/Documents/test_python_airflow/airflow/ssh_connection/custom_client.py", line 30, in client_conn
    raise(f"Error initiation ssh connection {e}")
TypeError: exceptions must derive from BaseException
[2024-09-17T12:03:39.965+0100] {processor.py:927} WARNING - No viable dags retrieved from /Users/ds2718/Documents/test_python_airflow/airflow/dags/examp_dag_sec.py
[2024-09-17T12:03:40.045+0100] {processor.py:208} INFO - Processing /Users/ds2718/Documents/test_python_airflow/airflow/dags/examp_dag_sec.py took 1.878 seconds
